Internal Server Error: /
Traceback (most recent call last):
  File "/usr/local/lib/python2.7/dist-packages/django/core/handlers/base.py", line 101, in get_response
    request.path_info)
  File "/usr/local/lib/python2.7/dist-packages/django/core/urlresolvers.py", line 298, in resolve
    for pattern in self.url_patterns:
  File "/usr/local/lib/python2.7/dist-packages/django/core/urlresolvers.py", line 328, in url_patterns
    patterns = getattr(self.urlconf_module, "urlpatterns", self.urlconf_module)
  File "/usr/local/lib/python2.7/dist-packages/django/core/urlresolvers.py", line 323, in urlconf_module
    self._urlconf_module = import_module(self.urlconf_name)
  File "/usr/local/lib/python2.7/dist-packages/django/utils/importlib.py", line 35, in import_module
    __import__(name)
  File "/home/justin/src/django_bodystats/src/django_bodystats/django_bodystats/urls.py", line 4, in <module>
    from JSONServer.api import *
ImportError: No module named JSONServer.api
Internal Server Error: /
Traceback (most recent call last):
  File "/usr/local/lib/python2.7/dist-packages/django/core/handlers/base.py", line 101, in get_response
    request.path_info)
  File "/usr/local/lib/python2.7/dist-packages/django/core/urlresolvers.py", line 298, in resolve
    for pattern in self.url_patterns:
  File "/usr/local/lib/python2.7/dist-packages/django/core/urlresolvers.py", line 328, in url_patterns
    patterns = getattr(self.urlconf_module, "urlpatterns", self.urlconf_module)
  File "/usr/local/lib/python2.7/dist-packages/django/core/urlresolvers.py", line 323, in urlconf_module
    self._urlconf_module = import_module(self.urlconf_name)
  File "/usr/local/lib/python2.7/dist-packages/django/utils/importlib.py", line 35, in import_module
    __import__(name)
  File "/home/justin/src/django_bodystats/src/django_bodystats/django_bodystats/urls.py", line 28, in <module>
    (r'^accounts/', include('allauth.urls'))
  File "/usr/local/lib/python2.7/dist-packages/django/conf/urls/__init__.py", line 24, in include
    urlconf_module = import_module(urlconf_module)
  File "/usr/local/lib/python2.7/dist-packages/django/utils/importlib.py", line 35, in import_module
    __import__(name)
  File "/usr/local/lib/python2.7/dist-packages/allauth/urls.py", line 15, in <module>
    url('^facebook/', include('allauth.facebook.urls')))
  File "/usr/local/lib/python2.7/dist-packages/django/conf/urls/__init__.py", line 24, in include
    urlconf_module = import_module(urlconf_module)
  File "/usr/local/lib/python2.7/dist-packages/django/utils/importlib.py", line 35, in import_module
    __import__(name)
  File "/usr/local/lib/python2.7/dist-packages/allauth/facebook/urls.py", line 3, in <module>
    import views
  File "/usr/local/lib/python2.7/dist-packages/allauth/facebook/views.py", line 18, in <module>
    from facebook import GraphAPI, GraphAPIError
ImportError: No module named facebook
Internal Server Error: /
Traceback (most recent call last):
  File "/usr/local/lib/python2.7/dist-packages/django/core/handlers/base.py", line 101, in get_response
    request.path_info)
  File "/usr/local/lib/python2.7/dist-packages/django/core/urlresolvers.py", line 298, in resolve
    for pattern in self.url_patterns:
  File "/usr/local/lib/python2.7/dist-packages/django/core/urlresolvers.py", line 328, in url_patterns
    patterns = getattr(self.urlconf_module, "urlpatterns", self.urlconf_module)
  File "/usr/local/lib/python2.7/dist-packages/django/core/urlresolvers.py", line 323, in urlconf_module
    self._urlconf_module = import_module(self.urlconf_name)
  File "/usr/local/lib/python2.7/dist-packages/django/utils/importlib.py", line 35, in import_module
    __import__(name)
  File "/home/justin/src/django_bodystats/src/django_bodystats/django_bodystats/urls.py", line 29, in <module>
    (r'^accounts/', include('allauth.urls'))
  File "/usr/local/lib/python2.7/dist-packages/django/conf/urls/__init__.py", line 24, in include
    urlconf_module = import_module(urlconf_module)
  File "/usr/local/lib/python2.7/dist-packages/django/utils/importlib.py", line 35, in import_module
    __import__(name)
  File "/usr/local/lib/python2.7/dist-packages/allauth/urls.py", line 15, in <module>
    url('^facebook/', include('allauth.facebook.urls')))
  File "/usr/local/lib/python2.7/dist-packages/django/conf/urls/__init__.py", line 24, in include
    urlconf_module = import_module(urlconf_module)
  File "/usr/local/lib/python2.7/dist-packages/django/utils/importlib.py", line 35, in import_module
    __import__(name)
  File "/usr/local/lib/python2.7/dist-packages/allauth/facebook/urls.py", line 3, in <module>
    import views
  File "/usr/local/lib/python2.7/dist-packages/allauth/facebook/views.py", line 18, in <module>
    from facebook import GraphAPI, GraphAPIError
ImportError: No module named facebook
Internal Server Error: /admin/
Traceback (most recent call last):
  File "/usr/local/lib/python2.7/dist-packages/django/core/handlers/base.py", line 101, in get_response
    request.path_info)
  File "/usr/local/lib/python2.7/dist-packages/django/core/urlresolvers.py", line 298, in resolve
    for pattern in self.url_patterns:
  File "/usr/local/lib/python2.7/dist-packages/django/core/urlresolvers.py", line 328, in url_patterns
    patterns = getattr(self.urlconf_module, "urlpatterns", self.urlconf_module)
  File "/usr/local/lib/python2.7/dist-packages/django/core/urlresolvers.py", line 323, in urlconf_module
    self._urlconf_module = import_module(self.urlconf_name)
  File "/usr/local/lib/python2.7/dist-packages/django/utils/importlib.py", line 35, in import_module
    __import__(name)
  File "/home/justin/src/django_bodystats/src/django_bodystats/django_bodystats/urls.py", line 29, in <module>
    (r'^accounts/', include('allauth.urls'))
  File "/usr/local/lib/python2.7/dist-packages/django/conf/urls/__init__.py", line 24, in include
    urlconf_module = import_module(urlconf_module)
  File "/usr/local/lib/python2.7/dist-packages/django/utils/importlib.py", line 35, in import_module
    __import__(name)
  File "/usr/local/lib/python2.7/dist-packages/allauth/urls.py", line 15, in <module>
    url('^facebook/', include('allauth.facebook.urls')))
  File "/usr/local/lib/python2.7/dist-packages/django/conf/urls/__init__.py", line 24, in include
    urlconf_module = import_module(urlconf_module)
  File "/usr/local/lib/python2.7/dist-packages/django/utils/importlib.py", line 35, in import_module
    __import__(name)
  File "/usr/local/lib/python2.7/dist-packages/allauth/facebook/urls.py", line 3, in <module>
    import views
  File "/usr/local/lib/python2.7/dist-packages/allauth/facebook/views.py", line 18, in <module>
    from facebook import GraphAPI, GraphAPIError
ImportError: No module named facebook
Internal Server Error: /admin/
Traceback (most recent call last):
  File "/usr/local/lib/python2.7/dist-packages/django/core/handlers/base.py", line 101, in get_response
    request.path_info)
  File "/usr/local/lib/python2.7/dist-packages/django/core/urlresolvers.py", line 298, in resolve
    for pattern in self.url_patterns:
  File "/usr/local/lib/python2.7/dist-packages/django/core/urlresolvers.py", line 328, in url_patterns
    patterns = getattr(self.urlconf_module, "urlpatterns", self.urlconf_module)
  File "/usr/local/lib/python2.7/dist-packages/django/core/urlresolvers.py", line 323, in urlconf_module
    self._urlconf_module = import_module(self.urlconf_name)
  File "/usr/local/lib/python2.7/dist-packages/django/utils/importlib.py", line 35, in import_module
    __import__(name)
  File "/home/justin/src/django_bodystats/src/django_bodystats/django_bodystats/urls.py", line 28, in <module>
    (r'^accounts/', include('allauth.urls'))
  File "/usr/local/lib/python2.7/dist-packages/django/conf/urls/__init__.py", line 24, in include
    urlconf_module = import_module(urlconf_module)
  File "/usr/local/lib/python2.7/dist-packages/django/utils/importlib.py", line 35, in import_module
    __import__(name)
  File "/usr/local/lib/python2.7/dist-packages/allauth/urls.py", line 15, in <module>
    url('^facebook/', include('allauth.facebook.urls')))
  File "/usr/local/lib/python2.7/dist-packages/django/conf/urls/__init__.py", line 24, in include
    urlconf_module = import_module(urlconf_module)
  File "/usr/local/lib/python2.7/dist-packages/django/utils/importlib.py", line 35, in import_module
    __import__(name)
  File "/usr/local/lib/python2.7/dist-packages/allauth/facebook/urls.py", line 3, in <module>
    import views
  File "/usr/local/lib/python2.7/dist-packages/allauth/facebook/views.py", line 18, in <module>
    from facebook import GraphAPI, GraphAPIError
ImportError: No module named facebook
Internal Server Error: /admin/
Traceback (most recent call last):
  File "/usr/local/lib/python2.7/dist-packages/django/core/handlers/base.py", line 101, in get_response
    request.path_info)
  File "/usr/local/lib/python2.7/dist-packages/django/core/urlresolvers.py", line 298, in resolve
    for pattern in self.url_patterns:
  File "/usr/local/lib/python2.7/dist-packages/django/core/urlresolvers.py", line 328, in url_patterns
    patterns = getattr(self.urlconf_module, "urlpatterns", self.urlconf_module)
  File "/usr/local/lib/python2.7/dist-packages/django/core/urlresolvers.py", line 323, in urlconf_module
    self._urlconf_module = import_module(self.urlconf_name)
  File "/usr/local/lib/python2.7/dist-packages/django/utils/importlib.py", line 35, in import_module
    __import__(name)
  File "/home/justin/src/django_bodystats/src/django_bodystats/django_bodystats/urls.py", line 29, in <module>
    (r'^accounts/', include('allauth.urls'))
  File "/usr/local/lib/python2.7/dist-packages/django/conf/urls/__init__.py", line 24, in include
    urlconf_module = import_module(urlconf_module)
  File "/usr/local/lib/python2.7/dist-packages/django/utils/importlib.py", line 35, in import_module
    __import__(name)
  File "/usr/local/lib/python2.7/dist-packages/allauth/urls.py", line 15, in <module>
    url('^facebook/', include('allauth.facebook.urls')))
  File "/usr/local/lib/python2.7/dist-packages/django/conf/urls/__init__.py", line 24, in include
    urlconf_module = import_module(urlconf_module)
  File "/usr/local/lib/python2.7/dist-packages/django/utils/importlib.py", line 35, in import_module
    __import__(name)
  File "/usr/local/lib/python2.7/dist-packages/allauth/facebook/urls.py", line 3, in <module>
    import views
  File "/usr/local/lib/python2.7/dist-packages/allauth/facebook/views.py", line 18, in <module>
    from facebook import GraphAPI, GraphAPIError
ImportError: No module named facebook
Internal Server Error: /
Traceback (most recent call last):
  File "/usr/local/lib/python2.7/dist-packages/django/core/handlers/base.py", line 111, in get_response
    response = callback(request, *callback_args, **callback_kwargs)
  File "/usr/local/lib/python2.7/dist-packages/django/contrib/auth/decorators.py", line 20, in _wrapped_view
    return view_func(request, *args, **kwargs)
  File "/home/justin/src/django_bodystats/src/django_bodystats/BodyStats/views.py", line 13, in index
    {'current_username': user.username})
  File "/usr/local/lib/python2.7/dist-packages/django/template/context.py", line 176, in __init__
    self.update(processor(request))
TypeError: 'str' object is not callable
Internal Server Error: /index.html
Traceback (most recent call last):
  File "/usr/local/lib/python2.7/dist-packages/django/core/handlers/base.py", line 89, in get_response
    response = middleware_method(request)
  File "/usr/local/lib/python2.7/dist-packages/django/middleware/common.py", line 67, in process_request
    if (not urlresolvers.is_valid_path(request.path_info, urlconf) and
  File "/usr/local/lib/python2.7/dist-packages/django/core/urlresolvers.py", line 531, in is_valid_path
    resolve(path, urlconf)
  File "/usr/local/lib/python2.7/dist-packages/django/core/urlresolvers.py", line 420, in resolve
    return get_resolver(urlconf).resolve(path)
  File "/usr/local/lib/python2.7/dist-packages/django/core/urlresolvers.py", line 298, in resolve
    for pattern in self.url_patterns:
  File "/usr/local/lib/python2.7/dist-packages/django/core/urlresolvers.py", line 328, in url_patterns
    patterns = getattr(self.urlconf_module, "urlpatterns", self.urlconf_module)
  File "/usr/local/lib/python2.7/dist-packages/django/core/urlresolvers.py", line 323, in urlconf_module
    self._urlconf_module = import_module(self.urlconf_name)
  File "/usr/local/lib/python2.7/dist-packages/django/utils/importlib.py", line 35, in import_module
    __import__(name)
  File "/home/justin/src/django_bodystats/src/django_bodystats/django_bodystats/urls.py", line 5
    from BodyStats.views import
                               ^
SyntaxError: invalid syntax
Internal Server Error: /index.html
Traceback (most recent call last):
  File "/usr/local/lib/python2.7/dist-packages/django/core/handlers/base.py", line 89, in get_response
    response = middleware_method(request)
  File "/usr/local/lib/python2.7/dist-packages/django/middleware/common.py", line 67, in process_request
    if (not urlresolvers.is_valid_path(request.path_info, urlconf) and
  File "/usr/local/lib/python2.7/dist-packages/django/core/urlresolvers.py", line 531, in is_valid_path
    resolve(path, urlconf)
  File "/usr/local/lib/python2.7/dist-packages/django/core/urlresolvers.py", line 420, in resolve
    return get_resolver(urlconf).resolve(path)
  File "/usr/local/lib/python2.7/dist-packages/django/core/urlresolvers.py", line 298, in resolve
    for pattern in self.url_patterns:
  File "/usr/local/lib/python2.7/dist-packages/django/core/urlresolvers.py", line 328, in url_patterns
    patterns = getattr(self.urlconf_module, "urlpatterns", self.urlconf_module)
  File "/usr/local/lib/python2.7/dist-packages/django/core/urlresolvers.py", line 323, in urlconf_module
    self._urlconf_module = import_module(self.urlconf_name)
  File "/usr/local/lib/python2.7/dist-packages/django/utils/importlib.py", line 35, in import_module
    __import__(name)
  File "/home/justin/src/django_bodystats/src/django_bodystats/django_bodystats/urls.py", line 5
    from BodyStats.views import
                               ^
SyntaxError: invalid syntax
Internal Server Error: /index.html
Traceback (most recent call last):
  File "/usr/local/lib/python2.7/dist-packages/django/core/handlers/base.py", line 89, in get_response
    response = middleware_method(request)
  File "/usr/local/lib/python2.7/dist-packages/django/middleware/common.py", line 67, in process_request
    if (not urlresolvers.is_valid_path(request.path_info, urlconf) and
  File "/usr/local/lib/python2.7/dist-packages/django/core/urlresolvers.py", line 531, in is_valid_path
    resolve(path, urlconf)
  File "/usr/local/lib/python2.7/dist-packages/django/core/urlresolvers.py", line 420, in resolve
    return get_resolver(urlconf).resolve(path)
  File "/usr/local/lib/python2.7/dist-packages/django/core/urlresolvers.py", line 298, in resolve
    for pattern in self.url_patterns:
  File "/usr/local/lib/python2.7/dist-packages/django/core/urlresolvers.py", line 328, in url_patterns
    patterns = getattr(self.urlconf_module, "urlpatterns", self.urlconf_module)
  File "/usr/local/lib/python2.7/dist-packages/django/core/urlresolvers.py", line 323, in urlconf_module
    self._urlconf_module = import_module(self.urlconf_name)
  File "/usr/local/lib/python2.7/dist-packages/django/utils/importlib.py", line 35, in import_module
    __import__(name)
  File "/home/justin/src/django_bodystats/src/django_bodystats/django_bodystats/urls.py", line 5
    from BodyStats.views import
                               ^
SyntaxError: invalid syntax
Internal Server Error: /index.html
Traceback (most recent call last):
  File "/usr/local/lib/python2.7/dist-packages/django/core/handlers/base.py", line 89, in get_response
    response = middleware_method(request)
  File "/usr/local/lib/python2.7/dist-packages/django/middleware/common.py", line 67, in process_request
    if (not urlresolvers.is_valid_path(request.path_info, urlconf) and
  File "/usr/local/lib/python2.7/dist-packages/django/core/urlresolvers.py", line 531, in is_valid_path
    resolve(path, urlconf)
  File "/usr/local/lib/python2.7/dist-packages/django/core/urlresolvers.py", line 420, in resolve
    return get_resolver(urlconf).resolve(path)
  File "/usr/local/lib/python2.7/dist-packages/django/core/urlresolvers.py", line 298, in resolve
    for pattern in self.url_patterns:
  File "/usr/local/lib/python2.7/dist-packages/django/core/urlresolvers.py", line 328, in url_patterns
    patterns = getattr(self.urlconf_module, "urlpatterns", self.urlconf_module)
  File "/usr/local/lib/python2.7/dist-packages/django/core/urlresolvers.py", line 323, in urlconf_module
    self._urlconf_module = import_module(self.urlconf_name)
  File "/usr/local/lib/python2.7/dist-packages/django/utils/importlib.py", line 35, in import_module
    __import__(name)
  File "/home/justin/src/django_bodystats/src/django_bodystats/django_bodystats/urls.py", line 5
    from BodyStats.views import
                               ^
SyntaxError: invalid syntax
Internal Server Error: /index.html
Traceback (most recent call last):
  File "/usr/local/lib/python2.7/dist-packages/django/core/handlers/base.py", line 111, in get_response
    response = callback(request, *callback_args, **callback_kwargs)
  File "/usr/local/lib/python2.7/dist-packages/django/contrib/auth/decorators.py", line 20, in _wrapped_view
    return view_func(request, *args, **kwargs)
TypeError: index() takes exactly 1 argument (3 given)
Internal Server Error: /index.html
Traceback (most recent call last):
  File "/usr/local/lib/python2.7/dist-packages/django/core/handlers/base.py", line 111, in get_response
    response = callback(request, *callback_args, **callback_kwargs)
  File "/usr/local/lib/python2.7/dist-packages/django/contrib/auth/decorators.py", line 20, in _wrapped_view
    return view_func(request, *args, **kwargs)
TypeError: index() takes exactly 1 argument (3 given)
Internal Server Error: /index.html
Traceback (most recent call last):
  File "/usr/local/lib/python2.7/dist-packages/django/core/handlers/base.py", line 111, in get_response
    response = callback(request, *callback_args, **callback_kwargs)
  File "/usr/local/lib/python2.7/dist-packages/django/contrib/auth/decorators.py", line 20, in _wrapped_view
    return view_func(request, *args, **kwargs)
TypeError: index() takes exactly 1 argument (3 given)
Internal Server Error: /index.html
Traceback (most recent call last):
  File "/usr/local/lib/python2.7/dist-packages/django/core/handlers/base.py", line 111, in get_response
    response = callback(request, *callback_args, **callback_kwargs)
  File "/usr/local/lib/python2.7/dist-packages/django/contrib/auth/decorators.py", line 20, in _wrapped_view
    return view_func(request, *args, **kwargs)
TypeError: index() takes exactly 1 argument (3 given)
Internal Server Error: /index.html
Traceback (most recent call last):
  File "/usr/local/lib/python2.7/dist-packages/django/core/handlers/base.py", line 111, in get_response
    response = callback(request, *callback_args, **callback_kwargs)
  File "/usr/local/lib/python2.7/dist-packages/django/contrib/auth/decorators.py", line 20, in _wrapped_view
    return view_func(request, *args, **kwargs)
TypeError: index() takes exactly 1 argument (3 given)
Internal Server Error: /index.html
Traceback (most recent call last):
  File "/usr/local/lib/python2.7/dist-packages/django/core/handlers/base.py", line 111, in get_response
    response = callback(request, *callback_args, **callback_kwargs)
  File "/usr/local/lib/python2.7/dist-packages/django/contrib/auth/decorators.py", line 20, in _wrapped_view
    return view_func(request, *args, **kwargs)
TypeError: index() takes exactly 1 argument (3 given)
Internal Server Error: /index.html
Traceback (most recent call last):
  File "/usr/local/lib/python2.7/dist-packages/django/core/handlers/base.py", line 111, in get_response
    response = callback(request, *callback_args, **callback_kwargs)
  File "/usr/local/lib/python2.7/dist-packages/django/contrib/auth/decorators.py", line 20, in _wrapped_view
    return view_func(request, *args, **kwargs)
TypeError: index() takes exactly 1 argument (3 given)
Not Found: /extjs/resources/css/ext-all.css
Not Found: /extjs/ext-debug.js
Not Found: /app.js
Not Found: /app.js
Not Found: /extjs/resources/css/ext-all.css
Not Found: /app.js
Not Found: /extjs/ext-debug.js
Not Found: /app.js
Internal Server Error: /api/v1/user/
Traceback (most recent call last):
  File "/usr/local/lib/python2.7/dist-packages/django/core/handlers/base.py", line 101, in get_response
    request.path_info)
  File "/usr/local/lib/python2.7/dist-packages/django/core/urlresolvers.py", line 298, in resolve
    for pattern in self.url_patterns:
  File "/usr/local/lib/python2.7/dist-packages/django/core/urlresolvers.py", line 328, in url_patterns
    patterns = getattr(self.urlconf_module, "urlpatterns", self.urlconf_module)
  File "/usr/local/lib/python2.7/dist-packages/django/core/urlresolvers.py", line 323, in urlconf_module
    self._urlconf_module = import_module(self.urlconf_name)
  File "/usr/local/lib/python2.7/dist-packages/django/utils/importlib.py", line 35, in import_module
    __import__(name)
  File "/home/justin/src/django_bodystats/src/django_bodystats/django_bodystats/urls.py", line 4, in <module>
    from BodyStats.api import *
  File "/home/justin/src/django_bodystats/src/django_bodystats/BodyStats/api.py", line 40
    return object_list.filter('id'=request.user)
SyntaxError: keyword can't be an expression
Internal Server Error: /api/v1/user/
Traceback (most recent call last):
  File "/usr/local/lib/python2.7/dist-packages/django/core/handlers/base.py", line 129, in get_response
    raise ValueError("The view %s.%s didn't return an HttpResponse object." % (callback.__module__, view_name))
ValueError: The view tastypie.resources.wrapper didn't return an HttpResponse object.
Internal Server Error: /api/v1/user/
Traceback (most recent call last):
  File "/usr/local/lib/python2.7/dist-packages/django/core/handlers/base.py", line 129, in get_response
    raise ValueError("The view %s.%s didn't return an HttpResponse object." % (callback.__module__, view_name))
ValueError: The view tastypie.resources.wrapper didn't return an HttpResponse object.
Internal Server Error: /api/v1/user/
Traceback (most recent call last):
  File "/usr/local/lib/python2.7/dist-packages/django/core/handlers/base.py", line 129, in get_response
    raise ValueError("The view %s.%s didn't return an HttpResponse object." % (callback.__module__, view_name))
ValueError: The view tastypie.resources.wrapper didn't return an HttpResponse object.
Internal Server Error: /api/v1/user/
Traceback (most recent call last):
  File "/usr/local/lib/python2.7/dist-packages/django/core/handlers/base.py", line 101, in get_response
    request.path_info)
  File "/usr/local/lib/python2.7/dist-packages/django/core/urlresolvers.py", line 298, in resolve
    for pattern in self.url_patterns:
  File "/usr/local/lib/python2.7/dist-packages/django/core/urlresolvers.py", line 328, in url_patterns
    patterns = getattr(self.urlconf_module, "urlpatterns", self.urlconf_module)
  File "/usr/local/lib/python2.7/dist-packages/django/core/urlresolvers.py", line 323, in urlconf_module
    self._urlconf_module = import_module(self.urlconf_name)
  File "/usr/local/lib/python2.7/dist-packages/django/utils/importlib.py", line 35, in import_module
    __import__(name)
  File "/home/justin/src/django_bodystats/src/django_bodystats/django_bodystats/urls.py", line 4, in <module>
    from BodyStats.api import *
  File "/home/justin/src/django_bodystats/src/django_bodystats/BodyStats/api.py", line 29, in <module>
    class UserResource(ModelResource):
  File "/home/justin/src/django_bodystats/src/django_bodystats/BodyStats/api.py", line 30, in UserResource
    class Meta:
  File "/home/justin/src/django_bodystats/src/django_bodystats/BodyStats/api.py", line 31, in Meta
    queryset = ger_user(request)
NameError: name 'ger_user' is not defined
Internal Server Error: /api/v1/user/
Traceback (most recent call last):
  File "/usr/local/lib/python2.7/dist-packages/django/core/handlers/base.py", line 101, in get_response
    request.path_info)
  File "/usr/local/lib/python2.7/dist-packages/django/core/urlresolvers.py", line 298, in resolve
    for pattern in self.url_patterns:
  File "/usr/local/lib/python2.7/dist-packages/django/core/urlresolvers.py", line 328, in url_patterns
    patterns = getattr(self.urlconf_module, "urlpatterns", self.urlconf_module)
  File "/usr/local/lib/python2.7/dist-packages/django/core/urlresolvers.py", line 323, in urlconf_module
    self._urlconf_module = import_module(self.urlconf_name)
  File "/usr/local/lib/python2.7/dist-packages/django/utils/importlib.py", line 35, in import_module
    __import__(name)
  File "/home/justin/src/django_bodystats/src/django_bodystats/django_bodystats/urls.py", line 4, in <module>
    from BodyStats.api import *
  File "/home/justin/src/django_bodystats/src/django_bodystats/BodyStats/api.py", line 29, in <module>
    class UserResource(ModelResource):
  File "/home/justin/src/django_bodystats/src/django_bodystats/BodyStats/api.py", line 30, in UserResource
    class Meta:
  File "/home/justin/src/django_bodystats/src/django_bodystats/BodyStats/api.py", line 31, in Meta
    queryset = get_user(request)
NameError: name 'request' is not defined
Not Found: /current_user
Internal Server Error: /current_user.html
Traceback (most recent call last):
  File "/usr/local/lib/python2.7/dist-packages/django/core/handlers/base.py", line 111, in get_response
    response = callback(request, *callback_args, **callback_kwargs)
  File "/home/justin/src/django_bodystats/src/django_bodystats/BodyStats/views.py", line 14, in current_user
    cu = serializers.serialize('json', get_user(request))
  File "/usr/local/lib/python2.7/dist-packages/django/core/serializers/__init__.py", line 98, in serialize
    s.serialize(queryset, **options)
  File "/usr/local/lib/python2.7/dist-packages/django/core/serializers/base.py", line 42, in serialize
    for obj in queryset:
TypeError: 'User' object is not iterable
Internal Server Error: /current_user.html
Traceback (most recent call last):
  File "/usr/local/lib/python2.7/dist-packages/django/core/handlers/base.py", line 111, in get_response
    response = callback(request, *callback_args, **callback_kwargs)
  File "/home/justin/src/django_bodystats/src/django_bodystats/BodyStats/views.py", line 15, in current_user
    cu = serializers.serialize('json', User.objects.get(pk=get_user(request).pk))
  File "/usr/local/lib/python2.7/dist-packages/django/core/serializers/__init__.py", line 98, in serialize
    s.serialize(queryset, **options)
  File "/usr/local/lib/python2.7/dist-packages/django/core/serializers/base.py", line 42, in serialize
    for obj in queryset:
TypeError: 'User' object is not iterable
Internal Server Error: /current_user.html
Traceback (most recent call last):
  File "/usr/local/lib/python2.7/dist-packages/django/core/handlers/base.py", line 111, in get_response
    response = callback(request, *callback_args, **callback_kwargs)
  File "/home/justin/src/django_bodystats/src/django_bodystats/BodyStats/views.py", line 15, in current_user
    cu = serializers.serialize('json', User.objects.get(pk=(get_user(request).pk)))
  File "/usr/local/lib/python2.7/dist-packages/django/core/serializers/__init__.py", line 98, in serialize
    s.serialize(queryset, **options)
  File "/usr/local/lib/python2.7/dist-packages/django/core/serializers/base.py", line 42, in serialize
    for obj in queryset:
TypeError: 'User' object is not iterable
Internal Server Error: /current_user.html
Traceback (most recent call last):
  File "/usr/local/lib/python2.7/dist-packages/django/core/handlers/base.py", line 111, in get_response
    response = callback(request, *callback_args, **callback_kwargs)
  File "/home/justin/src/django_bodystats/src/django_bodystats/BodyStats/views.py", line 16, in current_user
    cu = serializers.serialize('json', User.objects.get(pk=cupk))
  File "/usr/local/lib/python2.7/dist-packages/django/core/serializers/__init__.py", line 98, in serialize
    s.serialize(queryset, **options)
  File "/usr/local/lib/python2.7/dist-packages/django/core/serializers/base.py", line 42, in serialize
    for obj in queryset:
TypeError: 'User' object is not iterable
Internal Server Error: /current_user.html
Traceback (most recent call last):
  File "/usr/local/lib/python2.7/dist-packages/django/core/handlers/base.py", line 111, in get_response
    response = callback(request, *callback_args, **callback_kwargs)
  File "/home/justin/src/django_bodystats/src/django_bodystats/BodyStats/views.py", line 18, in current_user
    cu = serializers.serialize('json', User.objects.get(pk=cupk))
  File "/usr/local/lib/python2.7/dist-packages/django/core/serializers/__init__.py", line 98, in serialize
    s.serialize(queryset, **options)
  File "/usr/local/lib/python2.7/dist-packages/django/core/serializers/base.py", line 42, in serialize
    for obj in queryset:
TypeError: 'User' object is not iterable
Internal Server Error: /current_user.html
Traceback (most recent call last):
  File "/usr/local/lib/python2.7/dist-packages/django/core/handlers/base.py", line 111, in get_response
    response = callback(request, *callback_args, **callback_kwargs)
  File "/home/justin/src/django_bodystats/src/django_bodystats/BodyStats/views.py", line 14, in current_user
    cu = json.dumps(get_user(request))
  File "/usr/lib/python2.7/json/__init__.py", line 231, in dumps
    return _default_encoder.encode(obj)
  File "/usr/lib/python2.7/json/encoder.py", line 201, in encode
    chunks = self.iterencode(o, _one_shot=True)
  File "/usr/lib/python2.7/json/encoder.py", line 264, in iterencode
    return _iterencode(o, 0)
  File "/usr/lib/python2.7/json/encoder.py", line 178, in default
    raise TypeError(repr(o) + " is not JSON serializable")
TypeError: <User: admin> is not JSON serializable
Internal Server Error: /current_user.html
Traceback (most recent call last):
  File "/usr/local/lib/python2.7/dist-packages/django/core/handlers/base.py", line 111, in get_response
    response = callback(request, *callback_args, **callback_kwargs)
  File "/home/justin/src/django_bodystats/src/django_bodystats/BodyStats/views.py", line 14, in current_user
    cu = json.dumps(get_user(request).__dict__)
  File "/usr/lib/python2.7/json/__init__.py", line 231, in dumps
    return _default_encoder.encode(obj)
  File "/usr/lib/python2.7/json/encoder.py", line 201, in encode
    chunks = self.iterencode(o, _one_shot=True)
  File "/usr/lib/python2.7/json/encoder.py", line 264, in iterencode
    return _iterencode(o, 0)
  File "/usr/lib/python2.7/json/encoder.py", line 178, in default
    raise TypeError(repr(o) + " is not JSON serializable")
TypeError: <django.db.models.base.ModelState object at 0x7f4954487e10> is not JSON serializable
Not Found: /favicon.ico
Not Found: /favicon.ico
Not Found: /favicon.ico
Not Found: /favicon.ico
Not Found: /favicon.ico
Internal Server Error: /logout.json
Traceback (most recent call last):
  File "/usr/local/lib/python2.7/dist-packages/django/core/handlers/base.py", line 129, in get_response
    raise ValueError("The view %s.%s didn't return an HttpResponse object." % (callback.__module__, view_name))
ValueError: The view BodyStats.views.register_user didn't return an HttpResponse object.
Internal Server Error: /logout.json
Traceback (most recent call last):
  File "/usr/local/lib/python2.7/dist-packages/django/core/handlers/base.py", line 129, in get_response
    raise ValueError("The view %s.%s didn't return an HttpResponse object." % (callback.__module__, view_name))
ValueError: The view BodyStats.views.register_user didn't return an HttpResponse object.
Internal Server Error: /logout.json
Traceback (most recent call last):
  File "/usr/local/lib/python2.7/dist-packages/django/core/handlers/base.py", line 129, in get_response
    raise ValueError("The view %s.%s didn't return an HttpResponse object." % (callback.__module__, view_name))
ValueError: The view BodyStats.views.register_user didn't return an HttpResponse object.
Internal Server Error: /accounts/login/
Traceback (most recent call last):
  File "/usr/local/lib/python2.7/dist-packages/django/core/handlers/base.py", line 111, in get_response
    response = callback(request, *callback_args, **callback_kwargs)
  File "/usr/local/lib/python2.7/dist-packages/allauth/account/views.py", line 61, in login
    return render_to_response(template_name, RequestContext(request, ctx))
  File "/usr/local/lib/python2.7/dist-packages/django/shortcuts/__init__.py", line 20, in render_to_response
    return HttpResponse(loader.render_to_string(*args, **kwargs), **httpresponse_kwargs)
  File "/usr/local/lib/python2.7/dist-packages/django/template/loader.py", line 169, in render_to_string
    t = get_template(template_name)
  File "/usr/local/lib/python2.7/dist-packages/django/template/loader.py", line 145, in get_template
    template, origin = find_template(template_name)
  File "/usr/local/lib/python2.7/dist-packages/django/template/loader.py", line 138, in find_template
    raise TemplateDoesNotExist(name)
TemplateDoesNotExist: account/login.html
Not Found: /
Not Found: /
Internal Server Error: /accounts/login/
Traceback (most recent call last):
  File "/usr/local/lib/python2.7/dist-packages/django/core/handlers/base.py", line 111, in get_response
    response = callback(request, *callback_args, **callback_kwargs)
  File "/usr/local/lib/python2.7/dist-packages/allauth/account/views.py", line 61, in login
    return render_to_response(template_name, RequestContext(request, ctx))
  File "/usr/local/lib/python2.7/dist-packages/django/shortcuts/__init__.py", line 20, in render_to_response
    return HttpResponse(loader.render_to_string(*args, **kwargs), **httpresponse_kwargs)
  File "/usr/local/lib/python2.7/dist-packages/django/template/loader.py", line 169, in render_to_string
    t = get_template(template_name)
  File "/usr/local/lib/python2.7/dist-packages/django/template/loader.py", line 145, in get_template
    template, origin = find_template(template_name)
  File "/usr/local/lib/python2.7/dist-packages/django/template/loader.py", line 138, in find_template
    raise TemplateDoesNotExist(name)
TemplateDoesNotExist: account/login.html
Not Found: /accounts/
Internal Server Error: /accounts/login/
Traceback (most recent call last):
  File "/usr/local/lib/python2.7/dist-packages/django/core/handlers/base.py", line 111, in get_response
    response = callback(request, *callback_args, **callback_kwargs)
  File "/usr/local/lib/python2.7/dist-packages/allauth/account/views.py", line 61, in login
    return render_to_response(template_name, RequestContext(request, ctx))
  File "/usr/local/lib/python2.7/dist-packages/django/shortcuts/__init__.py", line 20, in render_to_response
    return HttpResponse(loader.render_to_string(*args, **kwargs), **httpresponse_kwargs)
  File "/usr/local/lib/python2.7/dist-packages/django/template/loader.py", line 169, in render_to_string
    t = get_template(template_name)
  File "/usr/local/lib/python2.7/dist-packages/django/template/loader.py", line 145, in get_template
    template, origin = find_template(template_name)
  File "/usr/local/lib/python2.7/dist-packages/django/template/loader.py", line 138, in find_template
    raise TemplateDoesNotExist(name)
TemplateDoesNotExist: account/login.html
Not Found: /accounts/login/
Not Found: /
Not Found: /accounts/login/
Not Found: /ststic/index.html
Not Found: /accounts/login/
Not Found: /accounts/login/
Not Found: /
Not Found: /accounts/login/
Not Found: /accounts/login/
Not Found: /accounts/login/
Not Found: /
Forbidden (CSRF token missing or incorrect.): /login
Internal Server Error: /admin/BodyStats/userprofile/
Traceback (most recent call last):
  File "/usr/local/lib/python2.7/dist-packages/django/core/handlers/base.py", line 111, in get_response
    response = callback(request, *callback_args, **callback_kwargs)
  File "/usr/local/lib/python2.7/dist-packages/django/contrib/admin/options.py", line 366, in wrapper
    return self.admin_site.admin_view(view)(*args, **kwargs)
  File "/usr/local/lib/python2.7/dist-packages/django/utils/decorators.py", line 91, in _wrapped_view
    response = view_func(request, *args, **kwargs)
  File "/usr/local/lib/python2.7/dist-packages/django/views/decorators/cache.py", line 89, in _wrapped_view_func
    response = view_func(request, *args, **kwargs)
  File "/usr/local/lib/python2.7/dist-packages/django/contrib/admin/sites.py", line 196, in inner
    return view(request, *args, **kwargs)
  File "/usr/local/lib/python2.7/dist-packages/django/utils/decorators.py", line 25, in _wrapper
    return bound_func(*args, **kwargs)
  File "/usr/local/lib/python2.7/dist-packages/django/utils/decorators.py", line 91, in _wrapped_view
    response = view_func(request, *args, **kwargs)
  File "/usr/local/lib/python2.7/dist-packages/django/utils/decorators.py", line 21, in bound_func
    return func(self, *args2, **kwargs2)
  File "/usr/local/lib/python2.7/dist-packages/django/contrib/admin/options.py", line 1233, in changelist_view
    'selection_note': _('0 of %(cnt)s selected') % {'cnt': len(cl.result_list)},
  File "/usr/local/lib/python2.7/dist-packages/django/db/models/query.py", line 85, in __len__
    self._result_cache = list(self.iterator())
  File "/usr/local/lib/python2.7/dist-packages/django/db/models/query.py", line 291, in iterator
    for row in compiler.results_iter():
  File "/usr/local/lib/python2.7/dist-packages/django/db/models/sql/compiler.py", line 763, in results_iter
    for rows in self.execute_sql(MULTI):
  File "/usr/local/lib/python2.7/dist-packages/django/db/models/sql/compiler.py", line 818, in execute_sql
    cursor.execute(sql, params)
  File "/usr/local/lib/python2.7/dist-packages/django/db/backends/util.py", line 40, in execute
    return self.cursor.execute(sql, params)
  File "/usr/local/lib/python2.7/dist-packages/django/db/backends/sqlite3/base.py", line 337, in execute
    return Database.Cursor.execute(self, query, params)
DatabaseError: no such column: BodyStats_userprofile.dob
Internal Server Error: /index.html
Traceback (most recent call last):
  File "/usr/local/lib/python2.7/dist-packages/django/core/handlers/base.py", line 89, in get_response
    response = middleware_method(request)
  File "/usr/local/lib/python2.7/dist-packages/django/middleware/common.py", line 67, in process_request
    if (not urlresolvers.is_valid_path(request.path_info, urlconf) and
  File "/usr/local/lib/python2.7/dist-packages/django/core/urlresolvers.py", line 531, in is_valid_path
    resolve(path, urlconf)
  File "/usr/local/lib/python2.7/dist-packages/django/core/urlresolvers.py", line 420, in resolve
    return get_resolver(urlconf).resolve(path)
  File "/usr/local/lib/python2.7/dist-packages/django/core/urlresolvers.py", line 298, in resolve
    for pattern in self.url_patterns:
  File "/usr/local/lib/python2.7/dist-packages/django/core/urlresolvers.py", line 328, in url_patterns
    patterns = getattr(self.urlconf_module, "urlpatterns", self.urlconf_module)
  File "/usr/local/lib/python2.7/dist-packages/django/core/urlresolvers.py", line 323, in urlconf_module
    self._urlconf_module = import_module(self.urlconf_name)
  File "/usr/local/lib/python2.7/dist-packages/django/utils/importlib.py", line 35, in import_module
    __import__(name)
  File "/home/justin/src/django_bodystats/src/django_bodystats/django_bodystats/urls.py", line 4, in <module>
    from BodyStats.api import *
  File "/home/justin/src/django_bodystats/src/django_bodystats/BodyStats/api.py", line 27, in <module>
    class UserResource(ModelResource):
  File "/home/justin/src/django_bodystats/src/django_bodystats/BodyStats/api.py", line 29, in UserResource
    class Meta:
  File "/home/justin/src/django_bodystats/src/django_bodystats/BodyStats/api.py", line 32, in Meta
    authentication = BasicAuthentication()
NameError: name 'BasicAuthentication' is not defined
Internal Server Error: /admin/
Traceback (most recent call last):
  File "/usr/local/lib/python2.7/dist-packages/django/core/handlers/base.py", line 101, in get_response
    request.path_info)
  File "/usr/local/lib/python2.7/dist-packages/django/core/urlresolvers.py", line 298, in resolve
    for pattern in self.url_patterns:
  File "/usr/local/lib/python2.7/dist-packages/django/core/urlresolvers.py", line 328, in url_patterns
    patterns = getattr(self.urlconf_module, "urlpatterns", self.urlconf_module)
  File "/usr/local/lib/python2.7/dist-packages/django/core/urlresolvers.py", line 323, in urlconf_module
    self._urlconf_module = import_module(self.urlconf_name)
  File "/usr/local/lib/python2.7/dist-packages/django/utils/importlib.py", line 35, in import_module
    __import__(name)
  File "/home/justin/src/django_bodystats/src/django_bodystats/django_bodystats/urls.py", line 4, in <module>
    from django_bodystats.BodyStats.api import *
ImportError: No module named BodyStats.api
Internal Server Error: /accounts/login/
Traceback (most recent call last):
  File "/usr/local/lib/python2.7/dist-packages/django/core/handlers/base.py", line 111, in get_response
    response = callback(request, *callback_args, **callback_kwargs)
  File "/usr/local/lib/python2.7/dist-packages/allauth/account/views.py", line 61, in login
    return render_to_response(template_name, RequestContext(request, ctx))
  File "/usr/local/lib/python2.7/dist-packages/django/shortcuts/__init__.py", line 20, in render_to_response
    return HttpResponse(loader.render_to_string(*args, **kwargs), **httpresponse_kwargs)
  File "/usr/local/lib/python2.7/dist-packages/django/template/loader.py", line 169, in render_to_string
    t = get_template(template_name)
  File "/usr/local/lib/python2.7/dist-packages/django/template/loader.py", line 145, in get_template
    template, origin = find_template(template_name)
  File "/usr/local/lib/python2.7/dist-packages/django/template/loader.py", line 138, in find_template
    raise TemplateDoesNotExist(name)
TemplateDoesNotExist: account/login.html
Internal Server Error: /accounts/login/
Traceback (most recent call last):
  File "/usr/local/lib/python2.7/dist-packages/django/core/handlers/base.py", line 111, in get_response
    response = callback(request, *callback_args, **callback_kwargs)
  File "/usr/local/lib/python2.7/dist-packages/allauth/account/views.py", line 61, in login
    return render_to_response(template_name, RequestContext(request, ctx))
  File "/usr/local/lib/python2.7/dist-packages/django/shortcuts/__init__.py", line 20, in render_to_response
    return HttpResponse(loader.render_to_string(*args, **kwargs), **httpresponse_kwargs)
  File "/usr/local/lib/python2.7/dist-packages/django/template/loader.py", line 169, in render_to_string
    t = get_template(template_name)
  File "/usr/local/lib/python2.7/dist-packages/django/template/loader.py", line 145, in get_template
    template, origin = find_template(template_name)
  File "/usr/local/lib/python2.7/dist-packages/django/template/loader.py", line 138, in find_template
    raise TemplateDoesNotExist(name)
TemplateDoesNotExist: account/login.html
Not Found: /accounts/
Internal Server Error: /current_user.json
Traceback (most recent call last):
  File "/usr/local/lib/python2.7/dist-packages/django/core/handlers/base.py", line 111, in get_response
    response = callback(request, *callback_args, **callback_kwargs)
  File "/home/justin/src/django_bodystats/src/django_bodystats/BodyStats/views.py", line 14, in current_user
    cus = json.dumps({'id': cu.pk,
AttributeError: 'AnonymousUser' object has no attribute 'pk'
Not Found: /register
Forbidden (CSRF token missing or incorrect.): /register
Forbidden (CSRF token missing or incorrect.): /register
Forbidden (CSRF token missing or incorrect.): /register
Forbidden (CSRF token missing or incorrect.): /register
Forbidden (CSRF token missing or incorrect.): /register
Internal Server Error: /register
Traceback (most recent call last):
  File "/usr/local/lib/python2.7/dist-packages/django/core/handlers/base.py", line 111, in get_response
    response = callback(request, *callback_args, **callback_kwargs)
  File "/home/justin/src/django_bodystats/src/django_bodystats/BodyStats/views.py", line 52, in register_user
    password=req_pass)
  File "/usr/local/lib/python2.7/dist-packages/django/contrib/auth/models.py", line 160, in create_user
    user.save(using=self._db)
  File "/usr/local/lib/python2.7/dist-packages/django/db/models/base.py", line 463, in save
    self.save_base(using=using, force_insert=force_insert, force_update=force_update)
  File "/usr/local/lib/python2.7/dist-packages/django/db/models/base.py", line 565, in save_base
    created=(not record_exists), raw=raw, using=using)
  File "/usr/local/lib/python2.7/dist-packages/django/dispatch/dispatcher.py", line 172, in send
    response = receiver(signal=self, sender=sender, **named)
  File "/home/justin/src/django_bodystats/src/django_bodystats/BodyStats/models.py", line 27, in create_user_profile
    UserProfile.objects.create(user=instance)
  File "/usr/local/lib/python2.7/dist-packages/django/db/models/manager.py", line 137, in create
    return self.get_query_set().create(**kwargs)
  File "/usr/local/lib/python2.7/dist-packages/django/db/models/query.py", line 377, in create
    obj.save(force_insert=True, using=self.db)
  File "/usr/local/lib/python2.7/dist-packages/django/db/models/base.py", line 463, in save
    self.save_base(using=using, force_insert=force_insert, force_update=force_update)
  File "/usr/local/lib/python2.7/dist-packages/django/db/models/base.py", line 551, in save_base
    result = manager._insert([self], fields=fields, return_id=update_pk, using=using, raw=raw)
  File "/usr/local/lib/python2.7/dist-packages/django/db/models/manager.py", line 203, in _insert
    return insert_query(self.model, objs, fields, **kwargs)
  File "/usr/local/lib/python2.7/dist-packages/django/db/models/query.py", line 1576, in insert_query
    return query.get_compiler(using=using).execute_sql(return_id)
  File "/usr/local/lib/python2.7/dist-packages/django/db/models/sql/compiler.py", line 910, in execute_sql
    cursor.execute(sql, params)
  File "/usr/local/lib/python2.7/dist-packages/django/db/backends/util.py", line 40, in execute
    return self.cursor.execute(sql, params)
  File "/usr/local/lib/python2.7/dist-packages/django/db/backends/sqlite3/base.py", line 337, in execute
    return Database.Cursor.execute(self, query, params)
IntegrityError: BodyStats_userprofile.height may not be NULL
Internal Server Error: /register
Traceback (most recent call last):
  File "/usr/local/lib/python2.7/dist-packages/django/core/handlers/base.py", line 111, in get_response
    response = callback(request, *callback_args, **callback_kwargs)
  File "/home/justin/src/django_bodystats/src/django_bodystats/BodyStats/views.py", line 52, in register_user
    password=req_pass)
  File "/usr/local/lib/python2.7/dist-packages/django/contrib/auth/models.py", line 160, in create_user
    user.save(using=self._db)
  File "/usr/local/lib/python2.7/dist-packages/django/db/models/base.py", line 463, in save
    self.save_base(using=using, force_insert=force_insert, force_update=force_update)
  File "/usr/local/lib/python2.7/dist-packages/django/db/models/base.py", line 565, in save_base
    created=(not record_exists), raw=raw, using=using)
  File "/usr/local/lib/python2.7/dist-packages/django/dispatch/dispatcher.py", line 172, in send
    response = receiver(signal=self, sender=sender, **named)
  File "/home/justin/src/django_bodystats/src/django_bodystats/BodyStats/models.py", line 27, in create_user_profile
    UserProfile.objects.create(user=instance)
  File "/usr/local/lib/python2.7/dist-packages/django/db/models/manager.py", line 137, in create
    return self.get_query_set().create(**kwargs)
  File "/usr/local/lib/python2.7/dist-packages/django/db/models/query.py", line 377, in create
    obj.save(force_insert=True, using=self.db)
  File "/usr/local/lib/python2.7/dist-packages/django/db/models/base.py", line 463, in save
    self.save_base(using=using, force_insert=force_insert, force_update=force_update)
  File "/usr/local/lib/python2.7/dist-packages/django/db/models/base.py", line 551, in save_base
    result = manager._insert([self], fields=fields, return_id=update_pk, using=using, raw=raw)
  File "/usr/local/lib/python2.7/dist-packages/django/db/models/manager.py", line 203, in _insert
    return insert_query(self.model, objs, fields, **kwargs)
  File "/usr/local/lib/python2.7/dist-packages/django/db/models/query.py", line 1576, in insert_query
    return query.get_compiler(using=using).execute_sql(return_id)
  File "/usr/local/lib/python2.7/dist-packages/django/db/models/sql/compiler.py", line 910, in execute_sql
    cursor.execute(sql, params)
  File "/usr/local/lib/python2.7/dist-packages/django/db/backends/util.py", line 40, in execute
    return self.cursor.execute(sql, params)
  File "/usr/local/lib/python2.7/dist-packages/django/db/backends/sqlite3/base.py", line 337, in execute
    return Database.Cursor.execute(self, query, params)
IntegrityError: BodyStats_userprofile.height may not be NULL
Internal Server Error: /register
Traceback (most recent call last):
  File "/usr/local/lib/python2.7/dist-packages/django/core/handlers/base.py", line 111, in get_response
    response = callback(request, *callback_args, **callback_kwargs)
  File "/home/justin/src/django_bodystats/src/django_bodystats/BodyStats/views.py", line 52, in register_user
    password=req_pass)
  File "/usr/local/lib/python2.7/dist-packages/django/contrib/auth/models.py", line 160, in create_user
    user.save(using=self._db)
  File "/usr/local/lib/python2.7/dist-packages/django/db/models/base.py", line 463, in save
    self.save_base(using=using, force_insert=force_insert, force_update=force_update)
  File "/usr/local/lib/python2.7/dist-packages/django/db/models/base.py", line 565, in save_base
    created=(not record_exists), raw=raw, using=using)
  File "/usr/local/lib/python2.7/dist-packages/django/dispatch/dispatcher.py", line 172, in send
    response = receiver(signal=self, sender=sender, **named)
  File "/home/justin/src/django_bodystats/src/django_bodystats/BodyStats/models.py", line 27, in create_user_profile
    UserProfile.objects.create(user=instance)
  File "/usr/local/lib/python2.7/dist-packages/django/db/models/manager.py", line 137, in create
    return self.get_query_set().create(**kwargs)
  File "/usr/local/lib/python2.7/dist-packages/django/db/models/query.py", line 377, in create
    obj.save(force_insert=True, using=self.db)
  File "/usr/local/lib/python2.7/dist-packages/django/db/models/base.py", line 463, in save
    self.save_base(using=using, force_insert=force_insert, force_update=force_update)
  File "/usr/local/lib/python2.7/dist-packages/django/db/models/base.py", line 551, in save_base
    result = manager._insert([self], fields=fields, return_id=update_pk, using=using, raw=raw)
  File "/usr/local/lib/python2.7/dist-packages/django/db/models/manager.py", line 203, in _insert
    return insert_query(self.model, objs, fields, **kwargs)
  File "/usr/local/lib/python2.7/dist-packages/django/db/models/query.py", line 1576, in insert_query
    return query.get_compiler(using=using).execute_sql(return_id)
  File "/usr/local/lib/python2.7/dist-packages/django/db/models/sql/compiler.py", line 910, in execute_sql
    cursor.execute(sql, params)
  File "/usr/local/lib/python2.7/dist-packages/django/db/backends/util.py", line 40, in execute
    return self.cursor.execute(sql, params)
  File "/usr/local/lib/python2.7/dist-packages/django/db/backends/sqlite3/base.py", line 337, in execute
    return Database.Cursor.execute(self, query, params)
IntegrityError: BodyStats_userprofile.height may not be NULL
Internal Server Error: /register
Traceback (most recent call last):
  File "/usr/local/lib/python2.7/dist-packages/django/core/handlers/base.py", line 111, in get_response
    response = callback(request, *callback_args, **callback_kwargs)
  File "/home/justin/src/django_bodystats/src/django_bodystats/BodyStats/views.py", line 52, in register_user
    password=req_pass)
  File "/usr/local/lib/python2.7/dist-packages/django/contrib/auth/models.py", line 160, in create_user
    user.save(using=self._db)
  File "/usr/local/lib/python2.7/dist-packages/django/db/models/base.py", line 463, in save
    self.save_base(using=using, force_insert=force_insert, force_update=force_update)
  File "/usr/local/lib/python2.7/dist-packages/django/db/models/base.py", line 551, in save_base
    result = manager._insert([self], fields=fields, return_id=update_pk, using=using, raw=raw)
  File "/usr/local/lib/python2.7/dist-packages/django/db/models/manager.py", line 203, in _insert
    return insert_query(self.model, objs, fields, **kwargs)
  File "/usr/local/lib/python2.7/dist-packages/django/db/models/query.py", line 1576, in insert_query
    return query.get_compiler(using=using).execute_sql(return_id)
  File "/usr/local/lib/python2.7/dist-packages/django/db/models/sql/compiler.py", line 910, in execute_sql
    cursor.execute(sql, params)
  File "/usr/local/lib/python2.7/dist-packages/django/db/backends/util.py", line 40, in execute
    return self.cursor.execute(sql, params)
  File "/usr/local/lib/python2.7/dist-packages/django/db/backends/sqlite3/base.py", line 337, in execute
    return Database.Cursor.execute(self, query, params)
IntegrityError: column username is not unique
Internal Server Error: /register
Traceback (most recent call last):
  File "/usr/local/lib/python2.7/dist-packages/django/core/handlers/base.py", line 111, in get_response
    response = callback(request, *callback_args, **callback_kwargs)
  File "/home/justin/src/django_bodystats/src/django_bodystats/BodyStats/views.py", line 52, in register_user
    password=req_pass)
  File "/usr/local/lib/python2.7/dist-packages/django/contrib/auth/models.py", line 160, in create_user
    user.save(using=self._db)
  File "/usr/local/lib/python2.7/dist-packages/django/db/models/base.py", line 463, in save
    self.save_base(using=using, force_insert=force_insert, force_update=force_update)
  File "/usr/local/lib/python2.7/dist-packages/django/db/models/base.py", line 551, in save_base
    result = manager._insert([self], fields=fields, return_id=update_pk, using=using, raw=raw)
  File "/usr/local/lib/python2.7/dist-packages/django/db/models/manager.py", line 203, in _insert
    return insert_query(self.model, objs, fields, **kwargs)
  File "/usr/local/lib/python2.7/dist-packages/django/db/models/query.py", line 1576, in insert_query
    return query.get_compiler(using=using).execute_sql(return_id)
  File "/usr/local/lib/python2.7/dist-packages/django/db/models/sql/compiler.py", line 910, in execute_sql
    cursor.execute(sql, params)
  File "/usr/local/lib/python2.7/dist-packages/django/db/backends/util.py", line 40, in execute
    return self.cursor.execute(sql, params)
  File "/usr/local/lib/python2.7/dist-packages/django/db/backends/sqlite3/base.py", line 337, in execute
    return Database.Cursor.execute(self, query, params)
IntegrityError: column username is not unique
Internal Server Error: /register
Traceback (most recent call last):
  File "/usr/local/lib/python2.7/dist-packages/django/core/handlers/base.py", line 111, in get_response
    response = callback(request, *callback_args, **callback_kwargs)
  File "/home/justin/src/django_bodystats/src/django_bodystats/BodyStats/views.py", line 52, in register_user
    password=req_pass)
  File "/usr/local/lib/python2.7/dist-packages/django/contrib/auth/models.py", line 160, in create_user
    user.save(using=self._db)
  File "/usr/local/lib/python2.7/dist-packages/django/db/models/base.py", line 463, in save
    self.save_base(using=using, force_insert=force_insert, force_update=force_update)
  File "/usr/local/lib/python2.7/dist-packages/django/db/models/base.py", line 565, in save_base
    created=(not record_exists), raw=raw, using=using)
  File "/usr/local/lib/python2.7/dist-packages/django/dispatch/dispatcher.py", line 172, in send
    response = receiver(signal=self, sender=sender, **named)
  File "/home/justin/src/django_bodystats/src/django_bodystats/BodyStats/models.py", line 27, in create_user_profile
    UserProfile.objects.create(user=instance)
  File "/usr/local/lib/python2.7/dist-packages/django/db/models/manager.py", line 137, in create
    return self.get_query_set().create(**kwargs)
  File "/usr/local/lib/python2.7/dist-packages/django/db/models/query.py", line 377, in create
    obj.save(force_insert=True, using=self.db)
  File "/usr/local/lib/python2.7/dist-packages/django/db/models/base.py", line 463, in save
    self.save_base(using=using, force_insert=force_insert, force_update=force_update)
  File "/usr/local/lib/python2.7/dist-packages/django/db/models/base.py", line 551, in save_base
    result = manager._insert([self], fields=fields, return_id=update_pk, using=using, raw=raw)
  File "/usr/local/lib/python2.7/dist-packages/django/db/models/manager.py", line 203, in _insert
    return insert_query(self.model, objs, fields, **kwargs)
  File "/usr/local/lib/python2.7/dist-packages/django/db/models/query.py", line 1576, in insert_query
    return query.get_compiler(using=using).execute_sql(return_id)
  File "/usr/local/lib/python2.7/dist-packages/django/db/models/sql/compiler.py", line 910, in execute_sql
    cursor.execute(sql, params)
  File "/usr/local/lib/python2.7/dist-packages/django/db/backends/util.py", line 40, in execute
    return self.cursor.execute(sql, params)
  File "/usr/local/lib/python2.7/dist-packages/django/db/backends/sqlite3/base.py", line 337, in execute
    return Database.Cursor.execute(self, query, params)
IntegrityError: BodyStats_userprofile.height may not be NULL
Internal Server Error: /admin/BodyStats/weight/
Traceback (most recent call last):
  File "/usr/local/lib/python2.7/dist-packages/django/core/handlers/base.py", line 136, in get_response
    response = response.render()
  File "/usr/local/lib/python2.7/dist-packages/django/template/response.py", line 104, in render
    self._set_content(self.rendered_content)
  File "/usr/local/lib/python2.7/dist-packages/django/template/response.py", line 81, in rendered_content
    content = template.render(context)
  File "/usr/local/lib/python2.7/dist-packages/django/template/base.py", line 140, in render
    return self._render(context)
  File "/usr/local/lib/python2.7/dist-packages/django/template/base.py", line 134, in _render
    return self.nodelist.render(context)
  File "/usr/local/lib/python2.7/dist-packages/django/template/base.py", line 823, in render
    bit = self.render_node(node, context)
  File "/usr/local/lib/python2.7/dist-packages/django/template/debug.py", line 74, in render_node
    return node.render(context)
  File "/usr/local/lib/python2.7/dist-packages/django/template/loader_tags.py", line 123, in render
    return compiled_parent._render(context)
  File "/usr/local/lib/python2.7/dist-packages/django/template/base.py", line 134, in _render
    return self.nodelist.render(context)
  File "/usr/local/lib/python2.7/dist-packages/django/template/base.py", line 823, in render
    bit = self.render_node(node, context)
  File "/usr/local/lib/python2.7/dist-packages/django/template/debug.py", line 74, in render_node
    return node.render(context)
  File "/usr/local/lib/python2.7/dist-packages/django/template/loader_tags.py", line 123, in render
    return compiled_parent._render(context)
  File "/usr/local/lib/python2.7/dist-packages/django/template/base.py", line 134, in _render
    return self.nodelist.render(context)
  File "/usr/local/lib/python2.7/dist-packages/django/template/base.py", line 823, in render
    bit = self.render_node(node, context)
  File "/usr/local/lib/python2.7/dist-packages/django/template/debug.py", line 74, in render_node
    return node.render(context)
  File "/usr/local/lib/python2.7/dist-packages/django/template/loader_tags.py", line 62, in render
    result = block.nodelist.render(context)
  File "/usr/local/lib/python2.7/dist-packages/django/template/base.py", line 823, in render
    bit = self.render_node(node, context)
  File "/usr/local/lib/python2.7/dist-packages/django/template/debug.py", line 74, in render_node
    return node.render(context)
  File "/usr/local/lib/python2.7/dist-packages/django/template/loader_tags.py", line 62, in render
    result = block.nodelist.render(context)
  File "/usr/local/lib/python2.7/dist-packages/django/template/base.py", line 823, in render
    bit = self.render_node(node, context)
  File "/usr/local/lib/python2.7/dist-packages/django/template/debug.py", line 74, in render_node
    return node.render(context)
  File "/usr/local/lib/python2.7/dist-packages/django/template/base.py", line 1178, in render
    _dict = func(*resolved_args, **resolved_kwargs)
  File "/usr/local/lib/python2.7/dist-packages/django/contrib/admin/templatetags/admin_list.py", line 278, in result_list
    'results': list(results(cl))}
  File "/usr/local/lib/python2.7/dist-packages/django/contrib/admin/templatetags/admin_list.py", line 256, in results
    yield ResultList(None, items_for_result(cl, res, None))
  File "/usr/local/lib/python2.7/dist-packages/django/contrib/admin/templatetags/admin_list.py", line 248, in __init__
    super(ResultList, self).__init__(*items)
  File "/usr/local/lib/python2.7/dist-packages/django/contrib/admin/templatetags/admin_list.py", line 176, in items_for_result
    f, attr, value = lookup_field(field_name, result, cl.model_admin)
  File "/usr/local/lib/python2.7/dist-packages/django/contrib/admin/util.py", line 246, in lookup_field
    value = attr()
  File "/usr/local/lib/python2.7/dist-packages/django/db/models/base.py", line 380, in __str__
    return force_unicode(self).encode('utf-8')
  File "/usr/local/lib/python2.7/dist-packages/django/utils/encoding.py", line 71, in force_unicode
    s = unicode(s)
  File "/home/justin/src/django_bodystats/src/django_bodystats/BodyStats/models.py", line 21, in __unicode__
    (self.user, self.timestamp, self.weight))
TypeError: an integer is required
Internal Server Error: /admin/BodyStats/weight/
Traceback (most recent call last):
  File "/usr/local/lib/python2.7/dist-packages/django/core/handlers/base.py", line 136, in get_response
    response = response.render()
  File "/usr/local/lib/python2.7/dist-packages/django/template/response.py", line 104, in render
    self._set_content(self.rendered_content)
  File "/usr/local/lib/python2.7/dist-packages/django/template/response.py", line 81, in rendered_content
    content = template.render(context)
  File "/usr/local/lib/python2.7/dist-packages/django/template/base.py", line 140, in render
    return self._render(context)
  File "/usr/local/lib/python2.7/dist-packages/django/template/base.py", line 134, in _render
    return self.nodelist.render(context)
  File "/usr/local/lib/python2.7/dist-packages/django/template/base.py", line 823, in render
    bit = self.render_node(node, context)
  File "/usr/local/lib/python2.7/dist-packages/django/template/debug.py", line 74, in render_node
    return node.render(context)
  File "/usr/local/lib/python2.7/dist-packages/django/template/loader_tags.py", line 123, in render
    return compiled_parent._render(context)
  File "/usr/local/lib/python2.7/dist-packages/django/template/base.py", line 134, in _render
    return self.nodelist.render(context)
  File "/usr/local/lib/python2.7/dist-packages/django/template/base.py", line 823, in render
    bit = self.render_node(node, context)
  File "/usr/local/lib/python2.7/dist-packages/django/template/debug.py", line 74, in render_node
    return node.render(context)
  File "/usr/local/lib/python2.7/dist-packages/django/template/loader_tags.py", line 123, in render
    return compiled_parent._render(context)
  File "/usr/local/lib/python2.7/dist-packages/django/template/base.py", line 134, in _render
    return self.nodelist.render(context)
  File "/usr/local/lib/python2.7/dist-packages/django/template/base.py", line 823, in render
    bit = self.render_node(node, context)
  File "/usr/local/lib/python2.7/dist-packages/django/template/debug.py", line 74, in render_node
    return node.render(context)
  File "/usr/local/lib/python2.7/dist-packages/django/template/loader_tags.py", line 62, in render
    result = block.nodelist.render(context)
  File "/usr/local/lib/python2.7/dist-packages/django/template/base.py", line 823, in render
    bit = self.render_node(node, context)
  File "/usr/local/lib/python2.7/dist-packages/django/template/debug.py", line 74, in render_node
    return node.render(context)
  File "/usr/local/lib/python2.7/dist-packages/django/template/loader_tags.py", line 62, in render
    result = block.nodelist.render(context)
  File "/usr/local/lib/python2.7/dist-packages/django/template/base.py", line 823, in render
    bit = self.render_node(node, context)
  File "/usr/local/lib/python2.7/dist-packages/django/template/debug.py", line 74, in render_node
    return node.render(context)
  File "/usr/local/lib/python2.7/dist-packages/django/template/base.py", line 1178, in render
    _dict = func(*resolved_args, **resolved_kwargs)
  File "/usr/local/lib/python2.7/dist-packages/django/contrib/admin/templatetags/admin_list.py", line 278, in result_list
    'results': list(results(cl))}
  File "/usr/local/lib/python2.7/dist-packages/django/contrib/admin/templatetags/admin_list.py", line 256, in results
    yield ResultList(None, items_for_result(cl, res, None))
  File "/usr/local/lib/python2.7/dist-packages/django/contrib/admin/templatetags/admin_list.py", line 248, in __init__
    super(ResultList, self).__init__(*items)
  File "/usr/local/lib/python2.7/dist-packages/django/contrib/admin/templatetags/admin_list.py", line 176, in items_for_result
    f, attr, value = lookup_field(field_name, result, cl.model_admin)
  File "/usr/local/lib/python2.7/dist-packages/django/contrib/admin/util.py", line 246, in lookup_field
    value = attr()
  File "/usr/local/lib/python2.7/dist-packages/django/db/models/base.py", line 380, in __str__
    return force_unicode(self).encode('utf-8')
  File "/usr/local/lib/python2.7/dist-packages/django/utils/encoding.py", line 71, in force_unicode
    s = unicode(s)
  File "/home/justin/src/django_bodystats/src/django_bodystats/BodyStats/models.py", line 21, in __unicode__
    (str(self.user), self.timestamp, self.weight))
TypeError: an integer is required
Internal Server Error: /register
Traceback (most recent call last):
  File "/usr/local/lib/python2.7/dist-packages/django/core/handlers/base.py", line 111, in get_response
    response = callback(request, *callback_args, **callback_kwargs)
  File "/home/justin/src/django_bodystats/src/django_bodystats/BodyStats/views.py", line 52, in register_user
    password=req_pass)
  File "/usr/local/lib/python2.7/dist-packages/django/contrib/auth/models.py", line 160, in create_user
    user.save(using=self._db)
  File "/usr/local/lib/python2.7/dist-packages/django/db/models/base.py", line 463, in save
    self.save_base(using=using, force_insert=force_insert, force_update=force_update)
  File "/usr/local/lib/python2.7/dist-packages/django/db/models/base.py", line 565, in save_base
    created=(not record_exists), raw=raw, using=using)
  File "/usr/local/lib/python2.7/dist-packages/django/dispatch/dispatcher.py", line 172, in send
    response = receiver(signal=self, sender=sender, **named)
  File "/home/justin/src/django_bodystats/src/django_bodystats/BodyStats/models.py", line 35, in create_user_profile
    UserProfile.objects.create(user=instance)
  File "/usr/local/lib/python2.7/dist-packages/django/db/models/manager.py", line 137, in create
    return self.get_query_set().create(**kwargs)
  File "/usr/local/lib/python2.7/dist-packages/django/db/models/query.py", line 377, in create
    obj.save(force_insert=True, using=self.db)
  File "/usr/local/lib/python2.7/dist-packages/django/db/models/base.py", line 463, in save
    self.save_base(using=using, force_insert=force_insert, force_update=force_update)
  File "/usr/local/lib/python2.7/dist-packages/django/db/models/base.py", line 551, in save_base
    result = manager._insert([self], fields=fields, return_id=update_pk, using=using, raw=raw)
  File "/usr/local/lib/python2.7/dist-packages/django/db/models/manager.py", line 203, in _insert
    return insert_query(self.model, objs, fields, **kwargs)
  File "/usr/local/lib/python2.7/dist-packages/django/db/models/query.py", line 1576, in insert_query
    return query.get_compiler(using=using).execute_sql(return_id)
  File "/usr/local/lib/python2.7/dist-packages/django/db/models/sql/compiler.py", line 910, in execute_sql
    cursor.execute(sql, params)
  File "/usr/local/lib/python2.7/dist-packages/django/db/backends/util.py", line 40, in execute
    return self.cursor.execute(sql, params)
  File "/usr/local/lib/python2.7/dist-packages/django/db/backends/sqlite3/base.py", line 337, in execute
    return Database.Cursor.execute(self, query, params)
IntegrityError: BodyStats_userprofile.height may not be NULL
Internal Server Error: /register
Traceback (most recent call last):
  File "/usr/local/lib/python2.7/dist-packages/django/core/handlers/base.py", line 111, in get_response
    response = callback(request, *callback_args, **callback_kwargs)
  File "/home/justin/src/django_bodystats/src/django_bodystats/BodyStats/views.py", line 52, in register_user
    password=req_pass)
  File "/usr/local/lib/python2.7/dist-packages/django/contrib/auth/models.py", line 160, in create_user
    user.save(using=self._db)
  File "/usr/local/lib/python2.7/dist-packages/django/db/models/base.py", line 463, in save
    self.save_base(using=using, force_insert=force_insert, force_update=force_update)
  File "/usr/local/lib/python2.7/dist-packages/django/db/models/base.py", line 565, in save_base
    created=(not record_exists), raw=raw, using=using)
  File "/usr/local/lib/python2.7/dist-packages/django/dispatch/dispatcher.py", line 172, in send
    response = receiver(signal=self, sender=sender, **named)
  File "/home/justin/src/django_bodystats/src/django_bodystats/BodyStats/models.py", line 35, in create_user_profile
    UserProfile.objects.create(user=instance)
  File "/usr/local/lib/python2.7/dist-packages/django/db/models/manager.py", line 137, in create
    return self.get_query_set().create(**kwargs)
  File "/usr/local/lib/python2.7/dist-packages/django/db/models/query.py", line 377, in create
    obj.save(force_insert=True, using=self.db)
  File "/usr/local/lib/python2.7/dist-packages/django/db/models/base.py", line 463, in save
    self.save_base(using=using, force_insert=force_insert, force_update=force_update)
  File "/usr/local/lib/python2.7/dist-packages/django/db/models/base.py", line 551, in save_base
    result = manager._insert([self], fields=fields, return_id=update_pk, using=using, raw=raw)
  File "/usr/local/lib/python2.7/dist-packages/django/db/models/manager.py", line 203, in _insert
    return insert_query(self.model, objs, fields, **kwargs)
  File "/usr/local/lib/python2.7/dist-packages/django/db/models/query.py", line 1576, in insert_query
    return query.get_compiler(using=using).execute_sql(return_id)
  File "/usr/local/lib/python2.7/dist-packages/django/db/models/sql/compiler.py", line 910, in execute_sql
    cursor.execute(sql, params)
  File "/usr/local/lib/python2.7/dist-packages/django/db/backends/util.py", line 40, in execute
    return self.cursor.execute(sql, params)
  File "/usr/local/lib/python2.7/dist-packages/django/db/backends/sqlite3/base.py", line 337, in execute
    return Database.Cursor.execute(self, query, params)
IntegrityError: BodyStats_userprofile.height may not be NULL
Internal Server Error: /register
Traceback (most recent call last):
  File "/usr/local/lib/python2.7/dist-packages/django/core/handlers/base.py", line 111, in get_response
    response = callback(request, *callback_args, **callback_kwargs)
  File "/home/justin/src/django_bodystats/src/django_bodystats/BodyStats/views.py", line 52, in register_user
    password=req_pass)
  File "/usr/local/lib/python2.7/dist-packages/django/contrib/auth/models.py", line 160, in create_user
    user.save(using=self._db)
  File "/usr/local/lib/python2.7/dist-packages/django/db/models/base.py", line 463, in save
    self.save_base(using=using, force_insert=force_insert, force_update=force_update)
  File "/usr/local/lib/python2.7/dist-packages/django/db/models/base.py", line 565, in save_base
    created=(not record_exists), raw=raw, using=using)
  File "/usr/local/lib/python2.7/dist-packages/django/dispatch/dispatcher.py", line 172, in send
    response = receiver(signal=self, sender=sender, **named)
  File "/home/justin/src/django_bodystats/src/django_bodystats/BodyStats/models.py", line 35, in create_user_profile
    UserProfile.objects.create(user=instance)
  File "/usr/local/lib/python2.7/dist-packages/django/db/models/manager.py", line 137, in create
    return self.get_query_set().create(**kwargs)
  File "/usr/local/lib/python2.7/dist-packages/django/db/models/query.py", line 377, in create
    obj.save(force_insert=True, using=self.db)
  File "/usr/local/lib/python2.7/dist-packages/django/db/models/base.py", line 463, in save
    self.save_base(using=using, force_insert=force_insert, force_update=force_update)
  File "/usr/local/lib/python2.7/dist-packages/django/db/models/base.py", line 551, in save_base
    result = manager._insert([self], fields=fields, return_id=update_pk, using=using, raw=raw)
  File "/usr/local/lib/python2.7/dist-packages/django/db/models/manager.py", line 203, in _insert
    return insert_query(self.model, objs, fields, **kwargs)
  File "/usr/local/lib/python2.7/dist-packages/django/db/models/query.py", line 1576, in insert_query
    return query.get_compiler(using=using).execute_sql(return_id)
  File "/usr/local/lib/python2.7/dist-packages/django/db/models/sql/compiler.py", line 910, in execute_sql
    cursor.execute(sql, params)
  File "/usr/local/lib/python2.7/dist-packages/django/db/backends/util.py", line 40, in execute
    return self.cursor.execute(sql, params)
  File "/usr/local/lib/python2.7/dist-packages/django/db/backends/sqlite3/base.py", line 337, in execute
    return Database.Cursor.execute(self, query, params)
IntegrityError: BodyStats_userprofile.height may not be NULL
Internal Server Error: /register
Traceback (most recent call last):
  File "/usr/local/lib/python2.7/dist-packages/django/core/handlers/base.py", line 111, in get_response
    response = callback(request, *callback_args, **callback_kwargs)
  File "/home/justin/src/django_bodystats/src/django_bodystats/BodyStats/views.py", line 52, in register_user
    password=req_pass)
  File "/usr/local/lib/python2.7/dist-packages/django/contrib/auth/models.py", line 160, in create_user
    user.save(using=self._db)
  File "/usr/local/lib/python2.7/dist-packages/django/db/models/base.py", line 463, in save
    self.save_base(using=using, force_insert=force_insert, force_update=force_update)
  File "/usr/local/lib/python2.7/dist-packages/django/db/models/base.py", line 551, in save_base
    result = manager._insert([self], fields=fields, return_id=update_pk, using=using, raw=raw)
  File "/usr/local/lib/python2.7/dist-packages/django/db/models/manager.py", line 203, in _insert
    return insert_query(self.model, objs, fields, **kwargs)
  File "/usr/local/lib/python2.7/dist-packages/django/db/models/query.py", line 1576, in insert_query
    return query.get_compiler(using=using).execute_sql(return_id)
  File "/usr/local/lib/python2.7/dist-packages/django/db/models/sql/compiler.py", line 910, in execute_sql
    cursor.execute(sql, params)
  File "/usr/local/lib/python2.7/dist-packages/django/db/backends/util.py", line 40, in execute
    return self.cursor.execute(sql, params)
  File "/usr/local/lib/python2.7/dist-packages/django/db/backends/sqlite3/base.py", line 337, in execute
    return Database.Cursor.execute(self, query, params)
IntegrityError: column username is not unique
Internal Server Error: /register
Traceback (most recent call last):
  File "/usr/local/lib/python2.7/dist-packages/django/core/handlers/base.py", line 111, in get_response
    response = callback(request, *callback_args, **callback_kwargs)
  File "/home/justin/src/django_bodystats/src/django_bodystats/BodyStats/views.py", line 52, in register_user
    password=req_pass)
  File "/usr/local/lib/python2.7/dist-packages/django/contrib/auth/models.py", line 160, in create_user
    user.save(using=self._db)
  File "/usr/local/lib/python2.7/dist-packages/django/db/models/base.py", line 463, in save
    self.save_base(using=using, force_insert=force_insert, force_update=force_update)
  File "/usr/local/lib/python2.7/dist-packages/django/db/models/base.py", line 565, in save_base
    created=(not record_exists), raw=raw, using=using)
  File "/usr/local/lib/python2.7/dist-packages/django/dispatch/dispatcher.py", line 172, in send
    response = receiver(signal=self, sender=sender, **named)
  File "/home/justin/src/django_bodystats/src/django_bodystats/BodyStats/models.py", line 35, in create_user_profile
    UserProfile.objects.create(user=instance)
  File "/usr/local/lib/python2.7/dist-packages/django/db/models/manager.py", line 137, in create
    return self.get_query_set().create(**kwargs)
  File "/usr/local/lib/python2.7/dist-packages/django/db/models/query.py", line 377, in create
    obj.save(force_insert=True, using=self.db)
  File "/usr/local/lib/python2.7/dist-packages/django/db/models/base.py", line 463, in save
    self.save_base(using=using, force_insert=force_insert, force_update=force_update)
  File "/usr/local/lib/python2.7/dist-packages/django/db/models/base.py", line 551, in save_base
    result = manager._insert([self], fields=fields, return_id=update_pk, using=using, raw=raw)
  File "/usr/local/lib/python2.7/dist-packages/django/db/models/manager.py", line 203, in _insert
    return insert_query(self.model, objs, fields, **kwargs)
  File "/usr/local/lib/python2.7/dist-packages/django/db/models/query.py", line 1576, in insert_query
    return query.get_compiler(using=using).execute_sql(return_id)
  File "/usr/local/lib/python2.7/dist-packages/django/db/models/sql/compiler.py", line 910, in execute_sql
    cursor.execute(sql, params)
  File "/usr/local/lib/python2.7/dist-packages/django/db/backends/util.py", line 40, in execute
    return self.cursor.execute(sql, params)
  File "/usr/local/lib/python2.7/dist-packages/django/db/backends/sqlite3/base.py", line 337, in execute
    return Database.Cursor.execute(self, query, params)
IntegrityError: BodyStats_userprofile.height may not be NULL
